package com.Nxer.TwistSpaceTechnology.common.modularizedMachine;

import static com.Nxer.TwistSpaceTechnology.common.modularizedMachine.ModularizedMachineLogic.ModularizedHatchElement.AllModule;
import static com.gtnewhorizon.structurelib.structure.StructureUtility.ofBlock;
import static com.gtnewhorizon.structurelib.structure.StructureUtility.transpose;
import static gregtech.api.enums.HatchElement.Energy;
import static gregtech.api.enums.HatchElement.ExoticEnergy;
import static gregtech.api.enums.HatchElement.InputBus;
import static gregtech.api.enums.HatchElement.InputHatch;
import static gregtech.api.enums.HatchElement.OutputBus;
import static gregtech.api.enums.HatchElement.OutputHatch;
import static gregtech.api.enums.Textures.BlockIcons.OVERLAY_DTPF_OFF;
import static gregtech.api.enums.Textures.BlockIcons.OVERLAY_DTPF_ON;
import static gregtech.api.enums.Textures.BlockIcons.OVERLAY_FUSION1_GLOW;
import static gregtech.api.util.GTStructureUtility.chainAllGlasses;
import static gregtech.api.util.GTStructureUtility.ofFrame;
import static tectech.thing.casing.TTCasingsContainer.sBlockCasingsTT;

import java.util.List;

import net.minecraft.item.ItemStack;
import net.minecraftforge.common.util.ForgeDirection;

import com.Nxer.TwistSpaceTechnology.common.modularizedMachine.ModularizedMachineLogic.MultiExecutionCoreMachineSupportAllModuleBase;
import com.Nxer.TwistSpaceTechnology.common.recipeMap.GTCMRecipe;
import com.Nxer.TwistSpaceTechnology.util.TSTUtils;
import com.Nxer.TwistSpaceTechnology.util.text.ID;
import com.Nxer.TwistSpaceTechnology.util.text.TSTMultiblockTooltipBuilder;
import com.Nxer.TwistSpaceTechnology.util.text.TSTSharedLocalization;
import com.cleanroommc.modularui.drawable.UITexture;
import com.gtnewhorizon.structurelib.structure.IStructureDefinition;
import com.gtnewhorizon.structurelib.structure.ISurvivalBuildEnvironment;
import com.gtnewhorizon.structurelib.structure.StructureDefinition;

import goodgenerator.loader.Loaders;
import gregtech.api.GregTechAPI;
import gregtech.api.enums.Materials;
import gregtech.api.enums.Textures;
import gregtech.api.interfaces.ITexture;
import gregtech.api.interfaces.metatileentity.IMetaTileEntity;
import gregtech.api.interfaces.metatileentity.IMetaTileEntity.SkipGenerateDescription;
import gregtech.api.interfaces.tileentity.IGregTechTileEntity;
import gregtech.api.recipe.RecipeMap;
import gregtech.api.render.TextureFactory;
import gregtech.api.structure.error.StructureError;
import gregtech.api.util.HatchElementBuilder;
import gregtech.api.util.MultiblockTooltipBuilder;
import gregtech.common.blocks.BlockCasings4;
import gregtech.common.blocks.BlockCasings8;

@SkipGenerateDescription
public class MM_LargeNeutronOscillator
    extends MultiExecutionCoreMachineSupportAllModuleBase<MM_LargeNeutronOscillator> {

    // region Class Constructor
    public MM_LargeNeutronOscillator(int aID, String aName, String aNameRegional) {
        super(aID, aName, aNameRegional);
        registerTooltipCredits(ID.NXER);
    }

    public MM_LargeNeutronOscillator(String aName) {
        super(aName);
    }

    @Override
    public IMetaTileEntity newMetaEntity(IGregTechTileEntity aTileEntity) {
        return new MM_LargeNeutronOscillator(this.mName);
    }
    // endregion

    // region Structure
    private static final int horizontalOffSet = 3;
    private static final int verticalOffSet = 36;
    private static final int depthOffSet = 1;
    private static final String STRUCTURE_PIECE_MAIN = "main";
    private static IStructureDefinition<MM_LargeNeutronOscillator> STRUCTURE_DEFINITION = null;

    @Override
    public IStructureDefinition<MM_LargeNeutronOscillator> getStructureDefinition() {
        if (null == STRUCTURE_DEFINITION) {
            STRUCTURE_DEFINITION = StructureDefinition.<MM_LargeNeutronOscillator>builder()
                .addShape(
                    STRUCTURE_PIECE_MAIN,
                    transpose(
                        // spotless:off
                        new String[][] {
                            { "                       ", "           CCCCCCCCCCC ", "           CCCCCCCCCCC ", "           CCCCCCCCCCC ", "           CCCCCCCCCCC ", "           CCCCCCCCCCC ", "           CCCCCCCCCCC ", "           CCCCCCCCCCC ", "           CCCCCCCCCCC ", "           CCCCCCCCCCC ", "           CCCCCCCCCCC ", "           CCCCCCCCCCC ", "                       " },
                            { "                       ", "            G       G  ", "           GFFFFFFFFFG ", "            FEFEFEFEF  ", "            FFFFFFFFF  ", "            FEFEFEFEF  ", "            FFFFFFFFF  ", "            FEFEFEFEF  ", "            FFFFFFFFF  ", "            FEFEFEFEF  ", "           GFFFFFFFFFG ", "            G       G  ", "                       " },
                            { "                       ", "            G       G  ", "           GFFFFFFFFFG ", "            FEFEFEFEF  ", "            FFFFFFFFF  ", "            FEFEFEFEF  ", "            FFFFFFFFF  ", "            FEFEFEFEF  ", "            FFFFFFFFF  ", "            FEFEFEFEF  ", "           GFFFFFFFFFG ", "            G       G  ", "                       " },
                            { "                       ", "            G       G  ", "           GFFFFFFFFFG ", "            FEFEFEFEF  ", "            FFFFFFFFF  ", "            FEFEFEFEF  ", "            FFFFFFFFF  ", "            FEFEFEFEF  ", "            FFFFFFFFF  ", "            FEFEFEFEF  ", "           GFFFFFFFFFG ", "            G       G  ", "                       " },
                            { "                       ", "            G       G  ", "           GFFFFFFFFFG ", "            FEFEFEFEF  ", "            FFFFFFFFF  ", "            FEFEFEFEF  ", "            FFFFFFFFF  ", "            FEFEFEFEF  ", "            FFFFFFFFF  ", "            FEFEFEFEF  ", "           GFFFFFFFFFG ", "            G       G  ", "                       " },
                            { "                       ", "            G       G  ", "           GFFFFFFFFFG ", "            FEFEFEFEF  ", "            FFFFFFFFF  ", "            FEFEFEFEF  ", "            FFFFFFFFF  ", "            FEFEFEFEF  ", "            FFFFFFFFF  ", "            FEFEFEFEF  ", "           GFFFFFFFFFG ", "            G       G  ", "                       " },
                            { "                       ", "            G       G  ", "           GFFFFFFFFFG ", "            FEFEFEFEF  ", "            FFFFFFFFF  ", "            FEFEFEFEF  ", "            FFFFFFFFF  ", "            FEFEFEFEF  ", "            FFFFFFFFF  ", "            FEFEFEFEF  ", "           GFFFFFFFFFG ", "            G       G  ", "                       " },
                            { "                       ", "            G       G  ", "           GFFFFFFFFFG ", "            FEFEFEFEF  ", "            FFFFFFFFF  ", "            FEFEFEFEF  ", "            FFFFFFFFF  ", "            FEFEFEFEF  ", "            FFFFFFFFF  ", "            FEFEFEFEF  ", "           GFFFFFFFFFG ", "            G       G  ", "                       " },
                            { "                       ", "            G       G  ", "           GFFFFFFFFFG ", "            FEFEFEFEF  ", "            FFFFFFFFF  ", "            FEFEFEFEF  ", "            FFFFFFFFF  ", "            FEFEFEFEF  ", "            FFFFFFFFF  ", "            FEFEFEFEF  ", "           GFFFFFFFFFG ", "            G       G  ", "                       " },
                            { "                       ", "            G       G  ", "           GFFFFFFFFFG ", "            FEFEFEFEF  ", "            FFFFFFFFF  ", "            FEFEFEFEF  ", "            FFFFFFFFF  ", "            FEFEFEFEF  ", "            FFFFFFFFF  ", "            FEFEFEFEF  ", "           GFFFFFFFFFG ", "            G       G  ", "                       " },
                            { "                       ", "            G       G  ", "           GFFFFFFFFFG ", "            FEFEFEFEF  ", "            FFFFFFFFF  ", "            FEFEFEFEF  ", "            FFFFFFFFF  ", "            FEFEFEFEF  ", "            FFFFFFFFF  ", "            FEFEFEFEF  ", "           GFFFFFFFFFG ", "            G       G  ", "                       " },
                            { "                       ", "            G       G  ", "           GFFFFFFFFFG ", "            FEFEFEFEF  ", "            FFFFFFFFF  ", "            FEFEFEFEF  ", "            FFFFFFFFF  ", "            FEFEFEFEF  ", "            FFFFFFFFF  ", "            FEFEFEFEF  ", "           GFFFFFFFFFG ", "            G       G  ", "                       " },
                            { "                       ", "            G       G  ", "           GFFFFFFFFFG ", "            FEFEFEFEF  ", "            FFFFFFFFF  ", "            FEFEFEFEF  ", "            FFFFFFFFF  ", "            FEFEFEFEF  ", "            FFFFFFFFF  ", "            FEFEFEFEF  ", "           GFFFFFFFFFG ", "            G       G  ", "                       " },
                            { "                       ", "            G       G  ", "           GFFFFFFFFFG ", "            FEFEFEFEF  ", "            FFFFFFFFF  ", "            FEFEFEFEF  ", "            FFFFFFFFF  ", "            FEFEFEFEF  ", "            FFFFFFFFF  ", "            FEFEFEFEF  ", "           GFFFFFFFFFG ", "            G       G  ", "                       " },
                            { "                       ", "            G       G  ", "           GFFFFFFFFFG ", "            FEFEFEFEF  ", "            FFFFFFFFF  ", "            FEFEFEFEF  ", "            FFFFFFFFF  ", "            FEFEFEFEF  ", "            FFFFFFFFF  ", "            FEFEFEFEF  ", "           GFFFFFFFFFG ", "            G       G  ", "                       " },
                            { "                       ", "            G       G  ", "           GFFFFFFFFFG ", "            FEFEFEFEF  ", "            FFFFFFFFF  ", "            FEFEFEFEF  ", "            FFFFFFFFF  ", "            FEFEFEFEF  ", "            FFFFFFFFF  ", "            FEFEFEFEF  ", "           GFFFFFFFFFG ", "            G       G  ", "                       " },
                            { "                       ", "            G       G  ", "           GFFFFFFFFFG ", "            FEFEFEFEF  ", "            FFFFFFFFF  ", "            FEFEFEFEF  ", "            FFFFFFFFF  ", "            FEFEFEFEF  ", "            FFFFFFFFF  ", "            FEFEFEFEF  ", "           GFFFFFFFFFG ", "            G       G  ", "                       " },
                            { "                       ", "            G       G  ", "           GFFFFFFFFFG ", "            FEFEFEFEF  ", "            FFFFFFFFF  ", "            FEFEFEFEF  ", "            FFFFFFFFF  ", "            FEFEFEFEF  ", "            FFFFFFFFF  ", "            FEFEFEFEF  ", "           GFFFFFFFFFG ", "            G       G  ", "                       " },
                            { "                       ", "            G       G  ", "           GFFFFFFFFFG ", "            FEFEFEFEF  ", "            FFFFFFFFF  ", "            FEFEFEFEF  ", "            FFFFFFFFF  ", "            FEFEFEFEF  ", "            FFFFFFFFF  ", "            FEFEFEFEF  ", "           GFFFFFFFFFG ", "            G       G  ", "                       " },
                            { "                       ", "            G       G  ", "           GFFFFFFFFFG ", "            FEFEFEFEF  ", "            FFFFFFFFF  ", "            FEFEFEFEF  ", "            FFFFFFFFF  ", "            FEFEFEFEF  ", "            FFFFFFFFF  ", "            FEFEFEFEF  ", "           GFFFFFFFFFG ", "            G       G  ", "                       " },
                            { "                       ", "            G       G  ", "           GFFFFFFFFFG ", "            FEFEFEFEF  ", "            FFFFFFFFF  ", "            FEFEFEFEF  ", "            FFFFFFFFF  ", "            FEFEFEFEF  ", "            FFFFFFFFF  ", "            FEFEFEFEF  ", "           GFFFFFFFFFG ", "            G       G  ", "                       " },
                            { "                       ", "            G       G  ", "           GFFFFFFFFFG ", "            FEFEFEFEF  ", "            FFFFFFFFF  ", "            FEFEFEFEF  ", "            FFFFFFFFF  ", "            FEFEFEFEF  ", "            FFFFFFFFF  ", "            FEFEFEFEF  ", "           GFFFFFFFFFG ", "            G       G  ", "                       " },
                            { "                       ", "            G       G  ", "           GFFFFFFFFFG ", "            FEFEFEFEF  ", "            FFFFFFFFF  ", "            FEFEFEFEF  ", "            FFFFFFFFF  ", "            FEFEFEFEF  ", "            FFFFFFFFF  ", "            FEFEFEFEF  ", "           GFFFFFFFFFG ", "            G       G  ", "                       " },
                            { "                       ", "            G       G  ", "           GFFFFFFFFFG ", "            FEFEFEFEF  ", "            FFFFFFFFF  ", "            FEFEFEFEF  ", "            FFFFFFFFF  ", "            FEFEFEFEF  ", "            FFFFFFFFF  ", "            FEFEFEFEF  ", "           GFFFFFFFFFG ", "            G       G  ", "                       " },
                            { "                       ", "            G       G  ", "           GFFFFFFFFFG ", "            FEFEFEFEF  ", "            FFFFFFFFF  ", "            FEFEFEFEF  ", "            FFFFFFFFF  ", "            FEFEFEFEF  ", "            FFFFFFFFF  ", "            FEFEFEFEF  ", "           GFFFFFFFFFG ", "            G       G  ", "                       " },
                            { "                       ", "            G       G  ", "           GFFFFFFFFFG ", "            FEFEFEFEF  ", "            FFFFFFFFF  ", "            FEFEFEFEF  ", "            FFFFFFFFF  ", "            FEFEFEFEF  ", "            FFFFFFFFF  ", "            FEFEFEFEF  ", "           GFFFFFFFFFG ", "            G       G  ", "                       " },
                            { "                       ", "            G       G  ", "           GFFFFFFFFFG ", "            FEFEFEFEF  ", "            FFFFFFFFF  ", "            FEFEFEFEF  ", "            FFFFFFFFF  ", "            FEFEFEFEF  ", "            FFFFFFFFF  ", "            FEFEFEFEF  ", "           GFFFFFFFFFG ", "            G       G  ", "                       " },
                            { "                       ", "            G       G  ", "           GFFFFFFFFFG ", "            FEFEFEFEF  ", "            FFFFFFFFF  ", "            FEFEFEFEF  ", "            FFFFFFFFF  ", "            FEFEFEFEF  ", "            FFFFFFFFF  ", "            FEFEFEFEF  ", "           GFFFFFFFFFG ", "            G       G  ", "                       " },
                            { "                       ", "            G       G  ", "           GFFFFFFFFFG ", "            FEFEFEFEF  ", "            FFFFFFFFF  ", "            FEFEFEFEF  ", "            FFFFFFFFF  ", "            FEFEFEFEF  ", "            FFFFFFFFF  ", "            FEFEFEFEF  ", "           GFFFFFFFFFG ", "            G       G  ", "                       " },
                            { "                       ", "            G       G  ", "           GFFFFFFFFFG ", "            FEFEFEFEF  ", "            FFFFFFFFF  ", "            FEFEFEFEF  ", "            FFFFFFFFF  ", "            FEFEFEFEF  ", "            FFFFFFFFF  ", "            FEFEFEFEF  ", "           GFFFFFFFFFG ", "            G       G  ", "                       " },
                            { "                       ", "            G       G  ", "           GFFFFFFFFFG ", "            FEFEFEFEF  ", "            FFFFFFFFF  ", "            FEFEFEFEF  ", "            FFFFFFFFF  ", "            FEFEFEFEF  ", "            FFFFFFFFF  ", "            FEFEFEFEF  ", "           GFFFFFFFFFG ", "            G       G  ", "                       " },
                            { "                       ", "            G       G  ", "           GFFFFFFFFFG ", "            FEFEFEFEF  ", "            FFFFFFFFF  ", "            FEFEFEFEF  ", "            FFFFFFFFF  ", "            FEFEFEFEF  ", "            FFFFFFFFF  ", "            FEFEFEFEF  ", "           GFFFFFFFFFG ", "            G       G  ", "                       " },
                            { "                       ", "            G       G  ", "           GFFFFFFFFFG ", "            FEFEFEFEF  ", "            FFFFFFFFF  ", "            FEFEFEFEF  ", "            FFFFFFFFF  ", "            FEFEFEFEF  ", "            FFFFFFFFF  ", "            FEFEFEFEF  ", "           GFFFFFFFFFG ", "            G       G  ", "                       " },
                            { "                       ", "            G       G  ", "           GFFFFFFFFFG ", "            FEFEFEFEF  ", "            FFFFFFFFF  ", "            FEFEFEFEF  ", "            FFFFFFFFF  ", "            FEFEFEFEF  ", "            FFFFFFFFF  ", "            FEFEFEFEF  ", "           GFFFFFFFFFG ", "            G       G  ", "                       " },
                            { "                       ", " CCCCC      G       G  ", " CCCCC     GFFFFFFFFFG ", " CCCCC      FEFEFEFEF  ", " CCCCC      FFFFFFFFF  ", " CCCCC      FEFEFEFEF  ", "            FFFFFFFFF  ", "            FEFEFEFEF  ", "            FFFFFFFFF  ", "            FEFEFEFEF  ", "           GFFFFFFFFFG ", "            G       G  ", "                       " },
                            { "                       ", " CAAAC      G       G  ", " CDDDC     GFFFFFFFFFG ", " CDDDC      FEFEFEFEF  ", " CDDDC      FFFFFFFFF  ", " CCCCC      FEFEFEFEF  ", "            FFFFFFFFF  ", "            FEFEFEFEF  ", "            FFFFFFFFF  ", "            FEFEFEFEF  ", "           GFFFFFFFFFG ", "            G       G  ", "                       " },
                            { "                       ", " CA~AC      G       G  ", " CDDDC     GFFFFFFFFFG ", " CDDDC      FEFEFEFEF  ", " CDDDC      FFFFFFFFF  ", " CCCCC      FEFEFEFEF  ", "            FFFFFFFFF  ", "            FEFEFEFEF  ", "            FFFFFFFFF  ", "            FEFEFEFEF  ", "           GFFFFFFFFFG ", "            G       G  ", "                       " },
                            { "                       ", " CAAAC      G       G  ", " CDDDC     GFFFFFFFFFG ", " CDDDC      FEFEFEFEF  ", " CDDDC      FFFFFFFFF  ", " CCCCC      FEFEFEFEF  ", "            FFFFFFFFF  ", "            FEFEFEFEF  ", "            FFFFFFFFF  ", "            FEFEFEFEF  ", "           GFFFFFFFFFG ", "            G       G  ", "                       " },
                            { "                       ", " CCCCC     CCCCCCCCCCC ", " CCCCCCCCCCCCCCCCCCCCC ", " CCCCCCCCCCCCCCCCCCCCC ", " CCCCCCCCCCCCCCCCCCCCC ", " CCCCC     CCCCCCCCCCC ", "           CCCCCCCCCCC ", "           CCCCCCCCCCC ", "           CCCCCCCCCCC ", "           CCCCCCCCCCC ", "           CCCCCCCCCCC ", "           CCCCCCCCCCC ", "                       " },
                            { "BBBBBBB   BBBBBBBBBBBBB", "BBBBBBBBBBBBBBBBBBBBBBB", "BBBBBBBBBBBBBBBBBBBBBBB", "BBBBBBBBBBBBBBBBBBBBBBB", "BBBBBBBBBBBBBBBBBBBBBBB", "BBBBBBBBBBBBBBBBBBBBBBB", "BBBBBBB   BBBBBBBBBBBBB", "          BBBBBBBBBBBBB", "          BBBBBBBBBBBBB", "          BBBBBBBBBBBBB", "          BBBBBBBBBBBBB", "          BBBBBBBBBBBBB", "          BBBBBBBBBBBBB" } }))
                // spotless:on
                .addElement(
                    'A',
                    HatchElementBuilder.<MM_LargeNeutronOscillator>builder()
                        .atLeast(AllModule)
                        .adder(MM_LargeNeutronOscillator::addModularHatchToMachineList)
                        .hint(1)
                        .casingIndex(((BlockCasings4) GregTechAPI.sBlockCasings4).getTextureIndex(1))
                        .buildAndChain(GregTechAPI.sBlockCasings4, 1))
                .addElement(
                    'B',
                    HatchElementBuilder.<MM_LargeNeutronOscillator>builder()
                        .atLeast(Energy.or(ExoticEnergy))
                        .adder(MM_LargeNeutronOscillator::addNormalHatchToMachineList)
                        .hint(2)
                        .casingIndex(((BlockCasings8) GregTechAPI.sBlockCasings8).getTextureIndex(7))
                        .buildAndChain(GregTechAPI.sBlockCasings8, 7))
                .addElement(
                    'C',
                    HatchElementBuilder.<MM_LargeNeutronOscillator>builder()
                        .atLeast(InputHatch, OutputHatch, InputBus, OutputBus)
                        .adder(MM_LargeNeutronOscillator::addNormalHatchToMachineList)
                        .hint(3)
                        .casingIndex(((BlockCasings8) GregTechAPI.sBlockCasings8).getTextureIndex(10))
                        .buildAndChain(GregTechAPI.sBlockCasings8, 10))
                .addElement('D', ofBlock(sBlockCasingsTT, 0))
                .addElement('E', ofBlock(Loaders.speedingPipe, 0))
                .addElement('F', chainAllGlasses())
                .addElement('G', ofFrame(Materials.NaquadahAlloy))
                .build();
            /*
             * A -> ofBlock...(gt.blockcasings4, 1, ...); module hatch
             * B -> ofBlock...(gt.blockcasings8, 7, ...); energy hatch
             * C -> ofBlock...(gt.blockcasings8, 10, ...); io hatch
             * D -> ofBlock...(gt.blockcasingsTT, 0, ...);
             * E -> ofBlock...(speedingPipe, 0, ...);
             * F -> ofBlock...(tile.glass, 0, ...);
             * G -> ofFrame...(Materials.NaquadahAlloy);
             */
        }
        return STRUCTURE_DEFINITION;
    }

    @Override
    public void construct(ItemStack stackSize, boolean hintsOnly) {
        buildPiece(STRUCTURE_PIECE_MAIN, stackSize, hintsOnly, horizontalOffSet, verticalOffSet, depthOffSet);
    }

    @Override
    public int survivalConstruct(ItemStack stackSize, int elementBudget, ISurvivalBuildEnvironment env) {
        if (mMachine) return -1;
        return survivalBuildPiece(
            STRUCTURE_PIECE_MAIN,
            stackSize,
            horizontalOffSet,
            verticalOffSet,
            depthOffSet,
            elementBudget,
            env,
            false,
            true);
    }

    @Override
    public boolean checkMachineMM(IGregTechTileEntity aBaseMetaTileEntity, ItemStack aStack,
        List<StructureError> errors) {
        return checkPiece(STRUCTURE_PIECE_MAIN, horizontalOffSet, verticalOffSet, depthOffSet, errors);
    }
    // endregion

    // region Processing Logic

    @Override
    public RecipeMap<?> getRecipeMap() {
        return GTCMRecipe.NeutronActivatorRecipesWithEU;
    }

    @Override
    public UITexture[] getMachineModeIcons() {
        return new UITexture[0];
    }

    @Override
    public boolean supportsSingleRecipeLocking() {
        return true;
    }

    @Override
    protected boolean canMultiplyModularHatchType() {
        return false;
    }

    // endregion

    // region Textures

    @Override
    public ITexture[] getTexture(IGregTechTileEntity baseMetaTileEntity, ForgeDirection sideDirection,
        ForgeDirection facingDirection, int colorIndex, boolean active, boolean redstoneLevel) {
        if (sideDirection == facingDirection) {
            if (active) return new ITexture[] { Textures.BlockIcons.getCasingTextureForId(49), TextureFactory.builder()
                .addIcon(OVERLAY_DTPF_ON)
                .extFacing()
                .build(),
                TextureFactory.builder()
                    .addIcon(OVERLAY_FUSION1_GLOW)
                    .extFacing()
                    .glow()
                    .build() };
            return new ITexture[] { Textures.BlockIcons.getCasingTextureForId(49), TextureFactory.builder()
                .addIcon(OVERLAY_DTPF_OFF)
                .extFacing()
                .build() };
        }
        return new ITexture[] { Textures.BlockIcons.getCasingTextureForId(49) };
    }

    // endregion

    // region Tooltip
    private static MultiblockTooltipBuilder tooltip;

    @Override
    protected MultiblockTooltipBuilder createTooltip() {
        if (tooltip == null) {
            tooltip = new TSTMultiblockTooltipBuilder();
            // spotless:off
            // #tr Tooltip_LargeNeutronOscillator_MachineType
            // # {\WHITE}Modularized Machine {\GRAY}- {\YELLOW}Neutron Activator
            // #zh_CN {\WHITE}模块化机械 {\GRAY}- {\YELLOW}中子活化器
            tooltip
                .addMachineType(
                    TSTUtils.tr("Tooltip_LargeNeutronOscillator_MachineType"))
                // #tr Tooltip_LargeNeutronOscillator_01
                // # {\AQUA}{\UNDERLINE}The more physics you know the less engineering you need.
                // #zh_CN {\AQUA}{\UNDERLINE}掌握的物理学越多， 需要的工程学越少。
                .addInfo(TSTUtils.tr("Tooltip_LargeNeutronOscillator_01"))

                // #tr Tooltip_LargeNeutronOscillator_02
                // # It consumes a lot of electricity to produce large quantities quickly.
                // #zh_CN 通过消耗大量电力来进行快速大批量生产.
                .addInfo(TSTUtils.tr("Tooltip_LargeNeutronOscillator_02"))

                // #tr Tooltip_LargeNeutronOscillator_03
                // # Installing module hatches near the controller block can significantly improve machine performance.
                // #zh_CN 在主机附近安装模块仓室可以显著提升机器性能.
                .addInfo(TSTUtils.tr("Tooltip_LargeNeutronOscillator_03"))
                .addStructureInfo(TSTSharedLocalization.ModularizedMachine.ModularizedMachineSystemDescription01)
                .addStructureInfo(TSTSharedLocalization.ModularizedMachine.ModularizedMachineSystemDescription02)
                .addStructureInfo(TSTSharedLocalization.ModularizedMachine.OverclockControllerDescription)
                .addStructureInfo(TSTSharedLocalization.ModularizedMachine.ParallelControllerDescription)
                .addStructureInfo(TSTSharedLocalization.ModularizedMachine.PowerConsumptionControllerDescription)
                .addStructureInfo(TSTSharedLocalization.ModularizedMachine.SpeedControllerDescription)
                .addStructureInfo(TSTSharedLocalization.ModularizedMachine.ExecutionCoreDescription)
                .addStructureInfo(TSTSharedLocalization.ModularizedMachine.NotMultiplyInstallSameTypeModule)
                .addStructureInfo(TSTSharedLocalization.General.Text_SeparatingLine)
                .beginStructureBlock(23, 40, 13, false)
                .addStructureInfo("  " + TSTSharedLocalization.ModularizedMachine.ModularHatch + ": " + TSTSharedLocalization.Structure.textUseBlueprint)
                .addEnergyHatch(TSTSharedLocalization.Structure.textUseBlueprint, 2)
                .addInputHatch(TSTSharedLocalization.Structure.textUseBlueprint, 3)
                .addOutputHatch(TSTSharedLocalization.Structure.textUseBlueprint, 3)
                .addInputBus(TSTSharedLocalization.Structure.textUseBlueprint, 3)
                .addOutputBus(TSTSharedLocalization.Structure.textUseBlueprint, 3)
                .addStructureHint(TSTSharedLocalization.ModularizedMachine.ModularHatchKey, 1)
                .toolTipFinisher();
            // spotless:on
        }
        return tooltip;
    }

    // endregion

}
