package com.Nxer.TwistSpaceTechnology.common.machine;

import static com.Nxer.TwistSpaceTechnology.common.block.BasicBlocks.MetaBlockCasing01;
import static com.Nxer.TwistSpaceTechnology.util.TextLocalization.ModName;
import static com.Nxer.TwistSpaceTechnology.util.TextLocalization.textUseBlueprint;
import static com.gtnewhorizon.structurelib.structure.StructureUtility.ofBlock;
import static com.gtnewhorizon.structurelib.structure.StructureUtility.transpose;
import static com.gtnewhorizon.structurelib.structure.StructureUtility.withChannel;
import static gregtech.api.enums.GT_HatchElement.Energy;
import static gregtech.api.enums.GT_HatchElement.ExoticEnergy;
import static gregtech.api.enums.GT_HatchElement.InputBus;
import static gregtech.api.enums.GT_HatchElement.OutputBus;
import static gregtech.api.util.GT_StructureUtility.ofFrame;
import static tb.init.TBBlocks.crystalBlock;
import static tuhljin.automagy.blocks.ModBlocks.translucent;

import net.minecraft.block.Block;
import net.minecraft.init.Blocks;
import net.minecraft.item.ItemStack;
import net.minecraftforge.common.util.ForgeDirection;

import com.Nxer.TwistSpaceTechnology.common.machine.multiMachineClasses.GTCM_MultiMachineBase;
import com.Nxer.TwistSpaceTechnology.util.LoaderReference;
import com.Nxer.TwistSpaceTechnology.util.TextEnums;
import com.github.bartimaeusnek.bartworks.API.BorosilicateGlass;
import com.gtnewhorizon.structurelib.structure.IStructureDefinition;
import com.gtnewhorizon.structurelib.structure.ISurvivalBuildEnvironment;
import com.gtnewhorizon.structurelib.structure.StructureDefinition;

import gregtech.api.GregTech_API;
import gregtech.api.enums.Materials;
import gregtech.api.enums.TAE;
import gregtech.api.enums.Textures;
import gregtech.api.interfaces.ITexture;
import gregtech.api.interfaces.metatileentity.IMetaTileEntity;
import gregtech.api.interfaces.tileentity.IGregTechTileEntity;
import gregtech.api.recipe.RecipeMap;
import gregtech.api.render.TextureFactory;
import gregtech.api.util.GT_HatchElementBuilder;
import gregtech.api.util.GT_Multiblock_Tooltip_Builder;
import gtPlusPlus.api.recipe.GTPPRecipeMaps;
import gtPlusPlus.core.block.ModBlocks;
import gtPlusPlus.xmod.gregtech.common.blocks.textures.TexturesGtBlock;

public class TST_MegaTreeFarm extends GTCM_MultiMachineBase<TST_MegaTreeFarm> {

    // region Class Constructor
    public TST_MegaTreeFarm(int aID, String aName, String aNameRegional) {
        super(aID, aName, aNameRegional);
    }

    public TST_MegaTreeFarm(String aName) {
        super(aName);
    }

    @Override
    public IMetaTileEntity newMetaEntity(IGregTechTileEntity aTileEntity) {
        return new TST_MegaTreeFarm(this.mName);
    }

    // region Processing Logic

    private Byte glassTier;

    @Override
    protected boolean isEnablePerfectOverclock() {
        return false;
    }

    @Override
    protected float getSpeedBonus() {
        return 1;
    }

    @Override
    protected int getMaxParallelRecipes() {
        return 1;
    }

    @Override
    public RecipeMap<?> getRecipeMap() {
        // Only for NEI, not used in processing logic.
        return GTPPRecipeMaps.treeGrowthSimulatorFakeRecipes;
    }

    @Override
    public boolean supportsInputSeparation() {
        return false;
    }

    @Override
    public boolean supportsBatchMode() {
        return false;
    }

    @Override
    public boolean supportsSingleRecipeLocking() {
        return false;
    }

    // region Structure

    private final int horizontalOffSet = 16;
    private final int verticalOffSet = 38;
    private final int depthOffSet = 7;
    private static final String STRUCTURE_PIECE_MAIN = "mainMegaTreeFarm";
    private static IStructureDefinition<TST_MegaTreeFarm> STRUCTURE_DEFINITION = null;

    @Override
    public void construct(ItemStack stackSize, boolean hintsOnly) {
        repairMachine();
        buildPiece(STRUCTURE_PIECE_MAIN, stackSize, hintsOnly, horizontalOffSet, verticalOffSet, depthOffSet);
    }

    @Override
    public boolean checkMachine(IGregTechTileEntity aBaseMetaTileEntity, ItemStack aStack) {
        repairMachine();
        return checkPiece(STRUCTURE_PIECE_MAIN, horizontalOffSet, verticalOffSet, depthOffSet);
    }

    @Override
    public int survivalConstruct(ItemStack stackSize, int elementBudget, ISurvivalBuildEnvironment env) {
        return survivialBuildPiece(
            STRUCTURE_PIECE_MAIN,
            stackSize,
            horizontalOffSet,
            verticalOffSet,
            depthOffSet,
            elementBudget,
            env,
            false,
            true);
    }

    @Override
    public IStructureDefinition<TST_MegaTreeFarm> getStructureDefinition() {
        if (STRUCTURE_DEFINITION == null) {
            STRUCTURE_DEFINITION = StructureDefinition.<TST_MegaTreeFarm>builder()
                .addShape(STRUCTURE_PIECE_MAIN, transpose(shape))
                .addElement(
                    'A',
                    withChannel(
                        "glass",
                        BorosilicateGlass.ofBoroGlass(
                            (byte) 0,
                            (byte) 1,
                            Byte.MAX_VALUE,
                            (te, t) -> te.glassTier = t,
                            te -> te.glassTier)))
                .addElement('B', ofBlock(MetaBlockCasing01, 9))
                .addElement('C', ofBlock(MetaBlockCasing01, 10))
                .addElement('D', ofBlock(GregTech_API.sBlockCasings1, 10))
                .addElement('E', ofBlock(GregTech_API.sBlockCasings8, 5))
                .addElement('F', ofBlock(GregTech_API.sBlockCasings8, 10))
                .addElement('G', ofBlock(GregTech_API.sBlockCasings9, 1))
                .addElement('H', ofBlock(ModBlocks.blockCasings2Misc, 15))
                .addElement('I', ofBlock(ModBlocks.blockCasingsTieredGTPP, 8))
                .addElement('J', ofBlock(translucent, 0))
                .addElement('K', ofBlock(crystalBlock, 2))
                .addElement('L', ofBlock(crystalBlock, 3))
                .addElement('M', ofBlock(Block.getBlockFromName("Forestry:soil"), 0))
                .addElement('N', ofBlock(Blocks.grass, 0))
                .addElement(
                    'O',
                    LoaderReference.ProjRedIllumination
                        ? ofBlock(Block.getBlockFromName("ProjRed|Illumination:projectred.illumination.lamp"), 10)
                        // : ofChain(ofBlock(Blocks.redstone_lamp, 0), ofBlock(Blocks.lit_redstone_lamp, 0)))
                        : ofBlock(Blocks.redstone_lamp, 0))
                .addElement('P', ofBlock(Blocks.water, 0))
                .addElement(
                    'Q',
                    GT_HatchElementBuilder.<TST_MegaTreeFarm>builder()
                        .atLeast(InputBus, OutputBus, Energy.or(ExoticEnergy))
                        .adder(TST_MegaTreeFarm::addToMachineList)
                        .dot(1)
                        .casingIndex(TAE.getIndexFromPage(1, 15))
                        .buildAndChain(ModBlocks.blockCasings2Misc, 15))
                .addElement(
                    'R',
                    GT_HatchElementBuilder.<TST_MegaTreeFarm>builder()
                        .atLeast(Energy.or(ExoticEnergy))
                        .adder(TST_MegaTreeFarm::addToMachineList)
                        .dot(2)
                        .casingIndex(TAE.getIndexFromPage(1, 15))
                        .buildAndChain(ModBlocks.blockCasings2Misc, 15))
                .addElement('S', ofFrame(Materials.Vulcanite))
                .build();
        }
        return STRUCTURE_DEFINITION;
    }

    @Override
    public ITexture[] getTexture(IGregTechTileEntity aBaseMetaTileEntity, ForgeDirection side, ForgeDirection aFacing,
        int colorIndex, boolean aActive, boolean redstoneLevel) {
        if (side == aFacing) {
            if (aActive) {
                return new ITexture[] { Textures.BlockIcons.getCasingTextureForId(TAE.getIndexFromPage(1, 15)),
                    TextureFactory.builder()
                        .addIcon(TexturesGtBlock.Overlay_Machine_Controller_Advanced)
                        .extFacing()
                        .build(),
                    TextureFactory.builder()
                        .addIcon(TexturesGtBlock.Overlay_Machine_Controller_Advanced_Active)
                        .extFacing()
                        .glow()
                        .build() };
            }

            return new ITexture[] { Textures.BlockIcons.getCasingTextureForId(TAE.getIndexFromPage(1, 15)),
                TextureFactory.builder()
                    .addIcon(TexturesGtBlock.Overlay_Machine_Controller_Advanced)
                    .extFacing()
                    .build() };
        }

        return new ITexture[] { Textures.BlockIcons.getCasingTextureForId(TAE.getIndexFromPage(1, 15)) };
    }

    // spotless:off

    /*
    A -> ofBlock...(BW_GlasBlocks, 0, ...);
    B -> ofBlock...(MetaBlockCasing01, 9, ...);
    C -> ofBlock...(MetaBlockCasing01, 10, ...);
    D -> ofBlock...(gt.blockcasings, 10, ...);
    E -> ofBlock...(gt.blockcasings8, 5, ...);
    F -> ofBlock...(gt.blockcasings8, 10, ...);
    G -> ofBlock...(gt.blockcasings9, 1, ...);
    H -> ofBlock...(gtplusplus.blockcasings.2, 15, ...);
    I -> ofBlock...(gtplusplus.blocktieredcasings.1, 8, ...);
    J -> ofBlock...(tile.blockTranslucent, 0, ...);
    K -> ofBlock...(tile.crystalBlock, 2, ...);
    L -> ofBlock...(tile.crystalBlock, 3, ...);
    M -> ofBlock...(tile.for.soil, 0, ...);
    N -> ofBlock...(tile.grass, 0, ...);
    O -> ofBlock...(tile.redstoneLight, 0, ...);
    P -> ofBlock...(tile.water, 0, ...);
    Q -> ofBlock...(tile.wood, 0, ...);     Any Hatch
    R -> ofBlock...(tile.wood, 1, ...);     Energy Hatch
    S -> ofSpecialTileAdder(gregtech.api.metatileentity.BaseMetaPipeEntity, ...);
    */

    private final String[][] shape = new String[][]{
        {"                                 ","                                 ","                                 ","                                 ","                                 ","                                 ","                                 ","                                 ","                                 ","                                 ","                                 ","                                 ","                                 ","              DDDDD              ","             DDDDDDD             ","             DDDDDDD             ","             DDDDDDD             ","             DDDDDDD             ","             DDDDDDD             ","              DDDDD              ","                                 ","                                 ","                                 ","                                 ","                                 ","                                 ","                                 ","                                 ","                                 ","                                 ","                                 ","                                 ","                                 "},
        {"                                 ","                                 ","                                 ","                                 ","                                 ","                                 ","                                 ","                                 ","                                 ","                                 ","               D D               ","             GGD DGG             ","            GGGD DGGG            ","           GGGHH HHGGG           ","           GGHSH HSHGG           ","          DDDHHH HHHDDD          ","                P                ","          DDDHHH HHHDDD          ","           GGHSH HSHGG           ","           GGGHH HHGGG           ","            GGGD DGGG            ","             GGD DGG             ","               D D               ","                                 ","                                 ","                                 ","                                 ","                                 ","                                 ","                                 ","                                 ","                                 ","                                 "},
        {"                                 ","                                 ","                                 ","                                 ","                                 ","                                 ","                                 ","                                 ","                                 ","             GGD DGG             ","           DGGGSDSGGGD           ","          DGG  SDS  GGD          ","          GG  HHDHH  GG          ","         GG  HIIDIIH  GG         ","         GG HIIIDIIIH GG         ","         DSSHIIIDIIIHSSD         ","          DDDDDDDDDDDDD          ","         DSSHIIIDIIIHSSD         ","         GG HIIIDIIIH GG         ","         GG  HIIDIIH  GG         ","          GG  HHDHH  GG          ","          DGG  SDS  GGD          ","           DGGGSDSGGGD           ","             GGD DGG             ","                                 ","                                 ","                                 ","                                 ","                                 ","                                 ","                                 ","                                 ","                                 "},
        {"                                 ","                                 ","                                 ","                                 ","                                 ","                                 ","                                 ","               D D               ","            DGGD DGGD            ","           AD  SDS  DA           ","          A     S     A          ","         A      S      A         ","        DD    DDDDD    DD        ","        G    DOOOOOD    G        ","        G   DOOOOOOOD   G        ","       DDS  DOOOOOOOD  SDD       ","         DSSDOOOOOOODSSD         ","       DDS  DOOOOOOOD  SDD       ","        G   DOOOOOOOD   G        ","        G    DOOOOOD    G        ","        DD    DDDDD    DD        ","         A      S      A         ","          A     S     A          ","           AD  SDS  DA           ","            DGGD DGGD            ","               D D               ","                                 ","                                 ","                                 ","                                 ","                                 ","                                 ","                                 "},
        {"                                 ","                                 ","                                 ","                                 ","                                 ","                                 ","               D D               ","            ADDSDSDDA            ","          AA   SDS   AA          ","         AA           AA         ","        AA             AA        ","        A               A        ","       A                 A       ","       D                 D       ","       D                 D       ","      DSS               SSD      ","       DD               DD       ","      DSS               SSD      ","       D                 D       ","       D                 D       ","       A                 A       ","        A               A        ","        AA             AA        ","         AA           AA         ","          AA   SDS   AA          ","            ADDSDSDDA            ","               D D               ","                                 ","                                 ","                                 ","                                 ","                                 ","                                 "},
        {"                                 ","                                 ","                                 ","                                 ","                                 ","                                 ","            AAAD DAAA            ","          AA   SDS   AA          ","         A             A         ","        A               A        ","       A                 A       ","       A                 A       ","      A                   A      ","      A                   A      ","      A                   A      ","      DS                 SD      ","       D                 D       ","      DS                 SD      ","      A                   A      ","      A                   A      ","      A                   A      ","       A                 A       ","       A                 A       ","        A               A        ","         A             A         ","          AA   SDS   AA          ","            AAAD DAAA            ","                                 ","                                 ","                                 ","                                 ","                                 ","                                 "},
        {"                                 ","                                 ","                                 ","                                 ","                                 ","             AAD DAA             ","           AA  SDS  AA           ","         AA           AA         ","        A               A        ","       A                 A       ","       A                 A       ","      A                   A      ","      A                   A      ","     A                     A     ","     A                     A     ","     DS                   SD     ","      D                   D      ","     DS                   SD     ","     A                     A     ","     A                     A     ","      A                   A      ","      A                   A      ","       A                 A       ","       A                 A       ","        A               A        ","         AA           AA         ","           AA  SDS  AA           ","             AAD DAA             ","                                 ","                                 ","                                 ","                                 ","                                 "},
        {"                                 ","                                 ","                                 ","                                 ","               D D               ","           AAAASDSAAAA           ","          A           A          ","        AA             AA        ","       A                 A       ","       A                 A       ","      A                   A      ","     A                     A     ","     A                     A     ","     A                     A     ","     A                     A     ","    DS                     SD    ","     D                     D     ","    DS                     SD    ","     A                     A     ","     A                     A     ","     A                     A     ","     A                     A     ","      A                   A      ","       A                 A       ","       A                 A       ","        AA             AA        ","          A           A          ","           AAAASDSAAAA           ","               D D               ","                                 ","                                 ","                                 ","                                 "},
        {"                                 ","                                 ","                                 ","                                 ","            DDDD DDDD            ","          DD   S S   DD          ","        DD             DD        ","       D                 D       ","      D                   D      ","      D                   D      ","     D                     D     ","     D                     D     ","    D                       D    ","    D                       D    ","    D                       D    ","    DS                     SD    ","                                 ","    DS                     SD    ","    D                       D    ","    D                       D    ","    D                       D    ","     D                     D     ","     D                     D     ","      D                   D      ","      D                   D      ","       D                 D       ","        DD             DD        ","          DD   S S   DD          ","            DDDD DDDD            ","                                 ","                                 ","                                 ","                                 "},
        {"                                 ","                                 ","                                 ","                                 ","            AAADDDAAA            ","          AA   S S   AA          ","        AA             AA        ","       A                 A       ","      A                   A      ","      A                   A      ","     A                     A     ","     A                     A     ","    A                       A    ","    A                       A    ","    A                       A    ","    DS                     SD    ","    D                       D    ","    DS                     SD    ","    A                       A    ","    A                       A    ","    A                       A    ","     A                     A     ","     A                     A     ","      A                   A      ","      A                   A      ","       A                 A       ","        AA             AA        ","          AA   S S   AA          ","            AAADDDAAA            ","                                 ","                                 ","                                 ","                                 "},
        {"                                 ","                                 ","                                 ","              AA AA              ","           AAA SDS AAA           ","         AA           AA         ","        A               A        ","       A                 A       ","      A                   A      ","     A                     A     ","     A                     A     ","    A                       A    ","    A                       A    ","    A                       A    ","   A                         A   ","   AS                       SA   ","    D                       D    ","   AS                       SA   ","    A                        A   ","    A                       A    ","    A                       A    ","    A                       A    ","     A                     A     ","     A                     A     ","      A                   A      ","       A                 A       ","        A               A        ","         AA           AA         ","           AAA SDS AAA           ","              AA AA              ","                                 ","                                 ","                                 "},
        {"                                 ","                                 ","                                 ","             AAADAAA             ","           AA       AA           ","         AA           AA         ","        A               A        ","       A                 A       ","      A                   A      ","     A                     A     ","     A                     A     ","    A                       A    ","    A                       A    ","   A                         A   ","   A                         A   ","   A                         A   ","   D                         D   ","   A                         A   ","   A                         A   ","   A                         A   ","    A                       A    ","    A                       A    ","     A                     A     ","     A                     A     ","      A                   A      ","       A                 A       ","        A               A        ","         AA           AA         ","           AA       AA           ","             AAADAAA             ","                                 ","                                 ","                                 "},
        {"                                 ","                                 ","                                 ","             AAADAAA             ","          AAA       AAA          ","         A             A         ","       AA               AA       ","      A                   A      ","      A                   A      ","     A                     A     ","    A                       A    ","    A                       A    ","    A                       A    ","   A                         A   ","   A                         A   ","   A                         A   ","   D                         D   ","   A                         A   ","   A                         A   ","   A                         A   ","    A                       A    ","    A                       A    ","    A                       A    ","     A                     A     ","      A                   A      ","      A                   A      ","       AA               AA       ","         A             A         ","          AAA       AAA          ","             AAADAAA             ","                                 ","                                 ","                                 "},
        {"                                 ","                                 ","                                 ","             AAADAAA             ","          AAA       AAA          ","         A             A         ","       AA               AA       ","      A                   A      ","      A                   A      ","     A                     A     ","    A                       A    ","    A                       A    ","    A                       A    ","   A                         A   ","   A                         A   ","   A                         A   ","   D                         D   ","   A                         A   ","   A                         A   ","   A                         A   ","    A                       A    ","    A                       A    ","    A                       A    ","     A                     A     ","      A                   A      ","      A                   A      ","       AA               AA       ","         A             A         ","          AAA       AAA          ","             AAADAAA             ","                                 ","                                 ","                                 "},
        {"                                 ","                                 ","                                 ","             AAADAAA             ","          AAA       AAA          ","         A             A         ","       AA               AA       ","      A                   A      ","      A                   A      ","     A                     A     ","    A                       A    ","    A                       A    ","    A                       A    ","   A                         A   ","   A                         A   ","   A                         A   ","   D                         D   ","   A                         A   ","   A                         A   ","   A                         A   ","    A                       A    ","    A                       A    ","    A                       A    ","     A                     A     ","      A                   A      ","      A                   A      ","       AA               AA       ","         A             A         ","          AAA       AAA          ","             AAADAAA             ","                                 ","                                 ","                                 "},
        {"                                 ","                                 ","                                 ","             AAADAAA             ","           AA       AA           ","         AA           AA         ","        A               A        ","       A                 A       ","      A                   A      ","     A                     A     ","     A                     A     ","    A                       A    ","    A                       A    ","   A                         A   ","   A                         A   ","   A                         A   ","   D                         D   ","   A                         A   ","   A                         A   ","   A                         A   ","    A                       A    ","    A                       A    ","     A                     A     ","     A                     A     ","      A                   A      ","       A                 A       ","        A               A        ","         AA           AA         ","           AA       AA           ","             AAADAAA             ","                                 ","                                 ","                                 "},
        {"                                 ","                                 ","                                 ","              AADAA              ","           AAA     AAA           ","         AA           AA         ","        A               A        ","       A                 A       ","      A                   A      ","     A                     A     ","     A                     A     ","    A                       A    ","    A                       A    ","    A                       A    ","   A                         A   ","   A                         A   ","   D                         D   ","   A                         A   ","   A                         A   ","    A                       A    ","    A                       A    ","    A                       A    ","     A                     A     ","     A                     A     ","      A                   A      ","       A                 A       ","        A               A        ","         AA           AA         ","           AAA     AAA           ","              AADAA              ","                                 ","                                 ","                                 "},
        {"                                 ","                                 ","                                 ","                                 ","            AAAADAAAA            ","          AA         AA          ","        AA             AA        ","       A                 A       ","      A                   A      ","      A                   A      ","     A                     A     ","     A                     A     ","    A                       A    ","    A                       A    ","    A                       A    ","    A                       A    ","    D                       D    ","    A                       A    ","    A                       A    ","    A                       A    ","    A                       A    ","     A                     A     ","     A                     A     ","      A                   A      ","      A                   A      ","       A                 A       ","        AA             AA        ","          AA         AA          ","            AAAADAAAA            ","                                 ","                                 ","                                 ","                                 "},
        {"                                 ","                                 ","                                 ","                                 ","             AAADAAA             ","          AAA       AAA          ","         A             A         ","        A               A        ","       A                 A       ","      A                   A      ","     A                     A     ","     A                     A     ","     A                     A     ","    A                       A    ","    A                       A    ","    A                       A    ","    D                       D    ","    A                       A    ","    A                       A    ","    A                       A    ","     A                     A     ","     A                     A     ","     A                     A     ","      A                   A      ","       A                 A       ","        A               A        ","         A             A         ","          AAA       AAA          ","             AAADAAA             ","                                 ","                                 ","                                 ","                                 "},
        {"                                 ","                                 ","                                 ","                                 ","               ADA               ","           AAAA   AAAA           ","          A           A          ","        AA             AA        ","       A                 A       ","       A                 A       ","      A                   A      ","     A                     A     ","     A                     A     ","     A                     A     ","     A                     A     ","    A                       A    ","    D                       D    ","    A                       A    ","     A                     A     ","     A                     A     ","     A                     A     ","     A                     A     ","      A                   A      ","       A                 A       ","       A                 A       ","        AA             AA        ","          A           A          ","           AAAA   AAAA           ","               ADA               ","                                 ","                                 ","                                 ","                                 "},
        {"                                 ","                                 ","                                 ","                                 ","                D                ","             AAAHAAA             ","           AA       AA           ","         AA           AA         ","        A               A        ","       A                 A       ","       A                 A       ","      A                   A      ","      A                   A      ","     A                     A     ","     A                     A     ","     A                     A     ","    DH                     HD    ","     A                     A     ","     A                     A     ","     A                     A     ","      A                   A      ","      A                   A      ","       A                 A       ","       A                 A       ","        A               A        ","         AA           AA         ","           AA       AA           ","             AAAHAAA             ","                D                ","                                 ","                                 ","                                 ","                                 "},
        {"                                 ","                                 ","                                 ","                                 ","                                 ","            DDDDDDDDD            ","          DDHHHHHHHHHDD          ","         DHHMMMM MMMMHHD         ","        DHMMMMMMMMMMMMMHD        ","       DHMMMMMMMMMMMMMMMHD       ","      DHMMMMMMMMMMMMMMMMMHD      ","      DHMMMMMMMMMMMMMMMMMHD      ","     DHMMMMMMMMMMMMMMMMMMMHD     ","     DHMMMMMMMMMMMMMMMMMMMHD     ","     DHMMMMMMMMMMMMMMMMMMMHD     ","     DHMMMMMMMMMMMMMMMMMMMHD     ","     DH MMMMMMMMMMMMMMMMM HD     ","     DHMMMMMMMMMMMMMMMMMMMHD     ","     DHMMMMMMMMMMMMMMMMMMMHD     ","     DHMMMMMMMMMMMMMMMMMMMHD     ","     DHMMMMMMMMMMMMMMMMMMMHD     ","      DHMMMMMMMMMMMMMMMMMHD      ","      DHMMMMMMMMMMMMMMMMMHD      ","       DHMMMMMMMMMMMMMMMHD       ","        DHMMMMMMMMMMMMMHD        ","         DHHMMMM MMMMHHD         ","          DDHHHHHHHHHDD          ","            DDDDDDDDD            ","                                 ","                                 ","                                 ","                                 ","                                 "},
        {"                                 ","                                 ","                                 ","                                 ","                                 ","                D                ","               AHA               ","            AAAM MAAA            ","          AAMMMM MMMMAA          ","         AAMMMMM MMMMMAA         ","        AAMMMMMMMMMMMMMAA        ","        AMMMMMMMMMMMMMMMA        ","       AMMMMMMMMMMMMMMMMMA       ","       AMMMMMMMMMMMMMMMMMA       ","       AMMMMMMMMMMMMMMMMMA       ","      AMMMMMMMMMMMMMMMMMMMA      ","     DH   MMMMMMMMMMMMM   HD     ","      AMMMMMMMMMMMMMMMMMMMA      ","       AMMMMMMMMMMMMMMMMMA       ","       AMMMMMMMMMMMMMMMMMA       ","       AMMMMMMMMMMMMMMMMMA       ","        AMMMMMMMMMMMMMMMA        ","        AAMMMMMMMMMMMMMAA        ","         AAMMMMM MMMMMAA         ","          AAMMMM MMMMAA          ","            AAAM MAAA            ","               AHA               ","                D                ","                                 ","                                 ","                                 ","                                 ","                                 "},
        {"                                 ","                                 ","                                 ","                                 ","                                 ","                                 ","                D                ","               AHA               ","            AAAAHAAAA            ","           AAMMM MMMAA           ","          AMMMMM MMMMMA          ","         AMMMMMMMMMMMMMA         ","        AAMMMMMMMMMMMMMAA        ","        AMMMMMMMMMMMMMMMA        ","        AMMMMMMMMMMMMMMMA        ","       AAMMMMMMMMMMMMMMMAA       ","      DHH  MMMMMMMMMMM  HHD      ","       AAMMMMMMMMMMMMMMMAA       ","        AMMMMMMMMMMMMMMMA        ","        AMMMMMMMMMMMMMMMA        ","        AAMMMMMMMMMMMMMAA        ","         AMMMMMMMMMMMMMA         ","          AMMMMM MMMMMA          ","           AAMMM MMMAA           ","            AAAAHAAAA            ","               AHA               ","                D                ","                                 ","                                 ","                                 ","                                 ","                                 ","                                 "},
        {"                                 ","                                 ","                                 ","                                 ","                                 ","                                 ","                                 ","                D                ","                D                ","             AAAHAAA             ","           AAAAM MAAAA           ","          AAAMMM MMMAAA          ","          AAMMMM MMMMAA          ","         AAMMMMM MMMMMAA         ","         AAMMMMMMMMMMMAA         ","         AMMMMMMMMMMMMMA         ","       DDH    MMMMM    HDD       ","         AMMMMMMMMMMMMMA         ","         AAMMMMMMMMMMMAA         ","         AAMMMMM MMMMMAA         ","          AAMMMM MMMMAA          ","          AAAMMM MMMAAA          ","           AAAAM MAAAA           ","             AAAHAAA             ","                D                ","                D                ","                                 ","                                 ","                                 ","                                 ","                                 ","                                 ","                                 "},
        {"                                 ","                                 ","                                 ","                                 ","                                 ","                                 ","                                 ","                                 ","                                 ","                D                ","               AHA               ","             AAAHAAA             ","            AAAAHAAAA            ","           AAAMM MMAAA           ","           AAMMM MMMAA           ","          AAAMMM MMMAAA          ","         DHHH       HHHD         ","          AAAMMM MMMAAA          ","           AAMMM MMMAA           ","           AAAMM MMAAA           ","            AAAAHAAAA            ","             AAAHAAA             ","               AHA               ","                D                ","                                 ","                                 ","                                 ","                                 ","                                 ","                                 ","                                 ","                                 ","                                 "},
        {"                                 ","                                 ","                                 ","                                 ","                                 ","                                 ","                                 ","                                 ","                                 ","                                 ","                D                ","                D                ","              DDDDD              ","             DHHHHHD             ","            DHHHHHHHD            ","            DHHHHHHHD            ","          DDDHHH HHHDDD          ","            DHHHHHHHD            ","            DHHHHHHHD            ","             DHHHHHD             ","              DDDDD              ","                D                ","                D                ","                                 ","                                 ","                                 ","                                 ","                                 ","                                 ","                                 ","                                 ","                                 ","                                 "},
        {"                                 ","                                 ","                                 ","                                 ","                                 ","                                 ","                                 ","                                 ","                                 ","                                 ","                                 ","                                 ","                                 ","              DDDDD              ","             DDJDJDD             ","             DJJDJJD             ","             DDD DDD             ","             DJJDJJD             ","             DDJDJDD             ","              DDDDD              ","                                 ","                                 ","                                 ","                                 ","                                 ","                                 ","                                 ","                                 ","                                 ","                                 ","                                 ","                                 ","                                 "},
        {"                                 ","                                 ","                                 ","                                 ","                                 ","                                 ","                                 ","                                 ","                                 ","                                 ","                                 ","                                 ","                                 ","                                 ","                                 ","                                 ","                                 ","                                 ","                                 ","                                 ","                                 ","                                 ","                                 ","                                 ","                                 ","                                 ","                                 ","                                 ","                                 ","                                 ","                                 ","                                 ","                                 "},
        {"                                 ","                                 ","                                 ","                                 ","                                 ","                                 ","                                 ","                                 ","                                 ","                                 ","                                 ","                                 ","                                 ","                                 ","                                 ","                                 ","                                 ","                                 ","                                 ","                                 ","                                 ","                                 ","                                 ","                                 ","                                 ","                                 ","                                 ","                                 ","                                 ","                                 ","                                 ","                                 ","                                 "},
        {"                                 ","                                 ","                                 ","                                 ","                                 ","                                 ","                                 ","                                 ","                                 ","                                 ","                                 ","                                 ","                                 ","                                 ","                                 ","                                 ","                                 ","                                 ","                                 ","                                 ","                                 ","                                 ","                                 ","                                 ","                                 ","                                 ","                                 ","                                 ","                                 ","                                 ","                                 ","                                 ","                                 "},
        {"                                 ","                                 ","                                 ","                                 ","                                 ","                                 ","                                 ","                                 ","                                 ","                                 ","                                 ","                                 ","                                 ","                                 ","                                 ","                                 ","                                 ","                                 ","                                 ","                                 ","                                 ","                                 ","                                 ","                                 ","                                 ","                                 ","                                 ","                                 ","                                 ","                                 ","                                 ","                                 ","                                 "},
        {"                                 ","                                 ","                                 ","                                 ","                                 ","                                 ","                                 ","                                 ","                                 ","                                 ","                                 ","                                 ","                                 ","                                 ","                                 ","                                 ","                K                ","                                 ","                                 ","                                 ","                                 ","                                 ","                                 ","                                 ","                                 ","                                 ","                                 ","                                 ","                                 ","                                 ","                                 ","                                 ","                                 "},
        {"                                 ","                                 ","                                 ","                                 ","                                 ","                                 ","                                 ","                                 ","                                 ","                                 ","                                 ","                                 ","                                 ","                                 ","                                 ","                                 ","                K                ","                                 ","                                 ","                                 ","                                 ","                                 ","                                 ","                                 ","                                 ","                                 ","                                 ","                                 ","                                 ","                                 ","                                 ","                                 ","                                 "},
        {"                                 ","                                 ","                                 ","                                 ","                                 ","                                 ","                                 ","                                 ","                                 ","                                 ","                                 ","                                 ","                                 ","                                 ","                                 ","                K                ","               KKK               ","                K                ","                                 ","                                 ","                                 ","                                 ","                                 ","                                 ","                                 ","                                 ","                                 ","                                 ","                                 ","                                 ","                                 ","                                 ","                                 "},
        {"                                 ","                                 ","                                 ","                                 ","                                 ","                                 ","                                 ","                                 ","                                 ","                                 ","                                 ","                                 ","                                 ","                                 ","                                 ","                K                ","               KKK               ","                K                ","                                 ","                                 ","                                 ","                                 ","                                 ","                                 ","                                 ","                                 ","                                 ","                                 ","                                 ","                                 ","                                 ","                                 ","                                 "},
        {"                                 ","                                 ","                                 ","                                 ","                                 ","                                 ","                                 ","                                 ","                                 ","                                 ","                                 ","                                 ","              EEEEE              ","             E     E             ","            E       E            ","            E   K   E            ","            E  KKK  E            ","            E   K   E            ","            E       E            ","             E     E             ","              EEEEE              ","                                 ","                                 ","                                 ","                                 ","                                 ","                                 ","                                 ","                                 ","                                 ","                                 ","                                 ","                                 "},
        {"                                 ","                                 ","                                 ","                                 ","                                 ","                                 ","                                 ","                                 ","             DDDDDDD             ","            DDSSSSSDD            ","          DDSSGGGGGSSDD          ","          DSGGGGGGGGGSD          ","         DSGGGEEEEEGGGSD         ","        DDSGGEBBBBBFGGSDD        ","        DSGGEBB   BBEGGSD        ","        DSGGEB     BEGGSD        ","        DSGGEB  J  BEGGSD        ","        DSGGEB     BEGGSD        ","        DSGGEBB   BBEGGSD        ","        DDSGGFBBBBBFGGSDD        ","         DSGGGEEEEEGGGSD         ","          DSGGGGGGGGGSD          ","          DDSSGGGGGSSDD          ","            DDSSSSSDD            ","             DDDDDDD             ","                                 ","                                 ","                                 ","                                 ","                                 ","                                 ","                                 ","                                 "},
        {"                                 ","                                 ","                                 ","                                 ","                                 ","                                 ","             D     D             ","             DSQ~QSD             ","            SDIIIIIDS            ","          SSIIIIIIIIISS          ","         SIIIIIIIIIIIIIS         ","         SIIIIIIIIIIIIIS         ","        SIIIIIEEEEEIIIIIS        ","      DDDIIIIELLLLLFIIIIDDD      ","       SIIIIELLBBBLLEIIIIS       ","       SIIIIELBBBBBLEIIIIS       ","       SIIIIELBBBBBLEIIIIS       ","       SIIIIELBBBBBLEIIIIS       ","       SIIIIELLBBBLLEIIIIS       ","      DDDIIIIFLLLLLFIIIIDDD      ","        SIIIIIEEEEEIIIIIS        ","         SIIIIIIIIIIIIIS         ","         SIIIIIIIIIIIIIS         ","          SSIIIIIIIIISS          ","            SDIIIIIDS            ","             DSSSSSD             ","             D     D             ","                                 ","                                 ","                                 ","                                 ","                                 ","                                 "},
        {"                                 ","                                 ","                                 ","                                 ","             DDDDDDD             ","           DDDQQQQQDDD           ","         DDQQHQQQQQHQQDD         ","        DQQQQHGHHHGHQQQQD        ","       DQQQQGHIIIIIHGQQQQD       ","      DQQQGGIIGGGGGIIGGQQQD      ","      DQQGIIGGGGGGGGGIIGQQD      ","     DQQQGIGGGGGGGGGGGIGQQQD     ","     DQQGIGGGGEEEEEGGGGIGQQD     ","    DDHHHIGGGELLLLLFGGGIHHHDD    ","    DQQGIGGGELLLLLLLEGGGIGQQD    ","    DQQGIGGGELLLLLLLEGGGIGQQD    ","    DQQGIGGGELLLLLLLEGGGIGQQD    ","    DQQGIGGGELLLLLLLEGGGIGQQD    ","    DQQGIGGGELLLLLLLEGGGIGQQD    ","    DDHHHIGGGFLLLLLFGGGIHHHDD    ","     DQQGIGGGGEEEEEGGGGIGQQD     ","     DQQQGIGGGGGGGGGGGIGQQQD     ","      DQQGIIGGGGGGGGGIIGQQD      ","      DQQQGGIIGGGGGIIGGQQQD      ","       DQQQQGHIIIIIHGQQQQD       ","        DQQQQHGGGGGHQQQQD        ","         DDQQHQQQQQHQQDD         ","           DDDQQQQQDDD           ","             DDDDDDD             ","                                 ","                                 ","                                 ","                                 "},
        {"                                 ","                                 ","                                 ","            DHHHHHHHD            ","           HDHHHDHHHDH           ","         HHHHDDDDDDDHHHH         ","        HHHDDCCCCCCCDDHHH        ","       HHDDCCCCCCCCCCCDDHH       ","      HHDCCCCCDDDDDCCCCCDHH      ","     HHDCCCCDDSSSSSDDCCCCDHH     ","     HHDCCDDSSSSSSSSSDDCCDHH     ","    HHDCCCDSSSSSSSSSSSDCCCDHH    ","   DDHDCCDSSSSEEEEESSSSDCCDHDD   ","   HHDCCCDSSSELLLLLFSSSDCCCDHH   ","   HHDCCDSSSELLLLLLLESSSDCCDHH   ","   HHDCCDSSSELLLLLLLESSSDCCDHH   ","   HDDCCDSSSELLLLLLLESSSDCCDDH   ","   HHDCCDSSSELLLLLLLESSSDCCDHH   ","   HHDCCDSSSELLLLLLLESSSDCCDHH   ","   HHDCCCDSSSFLLLLLFSSSDCCCDHH   ","   DDHDCCDSSSSEEEEESSSSDCCDHDD   ","    HHDCCCDSSSSSSSSSSSDCCCDHH    ","     HHDCCDDSSSSSSSSSDDCCDHH     ","     HHDCCCCDDSSSSSDDCCCCDHH     ","      HHDCCCCCDDDDDCCCCCDHH      ","       HHDDCCCCCCCCCCCDDHH       ","        HHHDDCCCCCCCDDHHH        ","         HHHHDDDDDDDHHHH         ","           HDHHHDHHHDH           ","            DHHHHHHHD            ","                                 ","                                 ","                                 "},
        {"                                 ","                                 ","            D       D            ","            SHHJJJHHS            ","           HHHHHDHHHHH           ","         JJHHCCCCCCCHHJJ         ","        HHHCCCCCCCCCCCHHH        ","       JHCCCCCCCCCCCCCCCHJ       ","      HHCCCCCCHHHHHCCCCCCHH      ","     JHCCCCCHHGGGGGHHCCCCCHJ     ","     JHCCCHHGGGGGGGGGHHCCCHJ     ","    HHCCCCHGGGGGGGGGGGHCCCCHH    ","  DSHHCCCHGGGGEEEEEGGGGHCCCHHSD  ","   HHCCCCHGGGELLLLLFGGGHCCCCHH   ","   HHCCCHGGGELLLLLLLEGGGHCCCHH   ","   JHCCCHGGGELLLLLLLEGGGHCCCHJ   ","   JDCCCHGGGELLLLLLLEGGGHCCCDJ   ","   JHCCCHGGGELLLLLLLEGGGHCCCHJ   ","   HHCCCHGGGELLLLLLLEGGGHCCCHH   ","   HHCCCCHGGGFLLLLLFGGGHCCCCHH   ","  DSHHCCCHGGGGEEEEEGGGGHCCCHHSD  ","    HHCCCCHGGGGGGGGGGGHCCCCHH    ","     JHCCCHHGGGGGGGGGHHCCCHJ     ","     JHCCCCCHHGGGGGHHCCCCCHJ     ","      HHCCCCCCHHHHHCCCCCCHH      ","       JHCCCCCCCCCCCCCCCHJ       ","        HHHCCCCCCCCCCCHHH        ","         JJHHCCCCCCCHHJJ         ","           HHHHHDHHHHH           ","            SHHJJJHHS            ","            D       D            ","                                 ","                                 "},
        {"                                 ","            D       D            ","            SS     SS            ","            SHRRRRRHS            ","           HHHHHDHHHHH           ","         HHHHHHHHHHHHHHH         ","        HHHRRHHHHHHHRRHHH        ","       HHRRRJRHHHHHRJRRRHH       ","      HHRRJRRRHHHHHRRRJRRHH      ","     HHRRRRRHH     HHRRRRRHH     ","     HHRJRHH         HHRJRHH     ","    HHRRRRH           HRRRRHH    "," DSSHHRJRH    EEEEE    HRJRHHSSD ","  SHHHHRRH   FLLLLLF   HRRHHHHS  ","   RHHHHH   ELLLLLLLE   HHHHHR   ","   RHHHHH   ELLLLLLLE   HHHHHR   ","   RDHHHH   ELLLLLLLE   HHHHDR   ","   RHHHHH   ELLLLLLLE   HHHHHR   ","   RHHHHH   ELLLLLLLE   HHHHHR   ","  SHHHHRRH   FLLLLLF   HRRHHHHS  "," DSSHHRJRH    EEEEE    HRJRHHSSD ","    HHRRRRH           HRRRRHH    ","     HHRJRHH         HHRJRHH     ","     HHRRRRRHH     HHRRRRRHH     ","      HHRRJRRRHHHHHRRRJRRHH      ","       HHRRRJRHHHHHRJRRRHH       ","        HHHRRHHHHHHHRRHHH        ","         HHHHHHHHHHHHHHH         ","           HHHHHDHHHHH           ","            SHRRRRRHS            ","            SS     SS            ","            D       D            ","                                 "},
        {"            DDDDDDDDD            ","            DSSSSSSSD            ","           DDD     DDD           ","           DDDDDDDDDDD           ","           DDDDDDDDDDD           ","         DDDDDDDDDDDDDDD         ","        DDD  DDDDDDD  DDD        ","       DD     DDDDD     DD       ","      DD      DDDDD      DD      ","     DD     DD     DD     DD     ","     DD   DD         DD   DD     ","  DDDD    D           D    DDDD  ","DDDDDD   D    EJJJE    D   DDDDDD","DSDDDDD  D   FLLLLLF   D  DDDDDSD","DS DDDDDD   ELLLLLLLE   DDDDDD SD","DS DDDDDD   JLLLLLLLJ   DDDDDD SD","DS DDDDDD   JLLLLLLLJ   DDDDDD SD","DS DDDDDD   JLLLLLLLJ   DDDDDD SD","DS DDDDDD   ELLLLLLLE   DDDDDD SD","DSDDDDD  D   FLLLLLF   D  DDDDDSD","DDDDDD   D    EJJJE    D   DDDDDD","  DDDD    D           D    DDDD  ","     DD   DD         DD   DD     ","     DD     DD     DD     DD     ","      DD      DDDDD      DD      ","       DD     DDDDD     DD       ","        DDD  DDDDDDD  DDD        ","         DDDDDDDDDDDDDDD         ","           DDDDDDDDDDD           ","           DDDDDDDDDDD           ","           DDD     DDD           ","            DSSSSSSSD            ","            DDDDDDDDD            "},
        {"            BBBBBBBBB            ","          BBB       BBB          ","        BBNBBB     BBBNBB        ","      BBNNNBBBBBBBBBBBNNNBB      ","     BNNNNNBBBBBBBBBBBNNNNNB     ","    BNNNNBBBBBBBBBBBBBBBNNNNB    ","   BNNNNBBB  BBBBBBB  BBBNNNNB   ","   BNNNBB     BBBBB     BBNNNB   ","  BNNNBB      BBBBB      BBNNNB  ","  BNNBB     BB     BB     BBNNB  "," BNNNBB   BB         BB   BBNNNB "," BBBBB    B           B    BBBBB ","BBBBBB   B    EEEEE    B   BBBBBB","B BBBBB  B   EFFFFFE   B  BBBBB B","B  BBBBBB   EFFLLLFFE   BBBBBB  B","B  BBBBBB   EFLLLLLFE   BBBBBB  B","B  BBBBBB   EFLLLLLFE   BBBBBB  B","B  BBBBBB   EFLLLLLFE   BBBBBB  B","B  BBBBBB   EFFLLLFFE   BBBBBB  B","B BBBBB  B   EFFFFFE   B  BBBBB B","BBBBBB   B    EEEEE    B   BBBBBB"," BBBBB    B           B    BBBBB "," BNNNBB   BB         BB   BBNNNB ","  BNNBB     BB     BB     BBNNB  ","  BNNNBB      BBBBB      BBNNNB  ","   BNNNBB     BBBBB     BBNNNB   ","   BNNNNBBB  BBBBBBB  BBBNNNNB   ","    BNNNNBBBBBBBBBBBBBBBNNNNB    ","     BNNNNNBBBBBBBBBBBNNNNNB     ","      BBNNNBBBBBBBBBBBNNNBB      ","        BBNBBB     BBBNBB        ","          BBB       BBB          ","            BBBBBBBBB            "}
    };
    @Override
    protected GT_Multiblock_Tooltip_Builder createTooltip() {
        final GT_Multiblock_Tooltip_Builder tt = new GT_Multiblock_Tooltip_Builder();
        // #tr Tooltip_MegaTreeFarm_MachineType
        // # Tree Farm
        // #zh_CN 树厂
        tt.addMachineType(TextEnums.tr("Tooltip_MegaTreeFarm_MachineType"))
            // #tr Tooltip_IndustrialMagnetarSeparator_Controller
            // # Controller block for the Mega Tree Growth Simulator
            // #zh_CN 巨型原木拟生厂的控制方块
            .addInfo(TextEnums.tr("Tooltip_MegaTreeFarm_Controller"))
            .addController(textUseBlueprint)
            .addInputBus(textUseBlueprint, 1)
            .addOutputBus(textUseBlueprint, 1)
            .addEnergyHatch(textUseBlueprint, 2)
            .toolTipFinisher(ModName);
        return tt;
    }

    // spotless:on
}
